{
 "cells": [
  {
   "cell_type": "code",
   "execution_count": 16,
   "metadata": {},
   "outputs": [],
   "source": [
    "import pandas as pd\n",
    "from keras.models import Sequential\n",
    "from keras.layers import Dense\n",
    "from sklearn.model_selection import cross_val_score\n",
    "from  scikeras.wrappers import KerasRegressor"
   ]
  },
  {
   "cell_type": "code",
   "execution_count": 17,
   "metadata": {},
   "outputs": [],
   "source": [
    "base = pd.read_csv('autos.csv', encoding = 'ISO-8859-1')\n",
    "base = base.drop('dateCrawled', axis = 1)\n",
    "base = base.drop('dateCreated', axis = 1)\n",
    "base = base.drop('nrOfPictures', axis = 1)\n",
    "base = base.drop('postalCode', axis = 1)\n",
    "base = base.drop('lastSeen', axis = 1)\n",
    "base = base.drop('name', axis = 1)\n",
    "base = base.drop('seller', axis = 1)\n",
    "base = base.drop('offerType', axis = 1)"
   ]
  },
  {
   "cell_type": "code",
   "execution_count": 18,
   "metadata": {},
   "outputs": [],
   "source": [
    "valores = {'vehicleType': 'limousine', 'gearbox': 'manuell', \n",
    "           'model': 'golf', 'fuelType': 'benzin', \n",
    "           'notRepairedDamage': 'nein'}"
   ]
  },
  {
   "cell_type": "code",
   "execution_count": 19,
   "metadata": {},
   "outputs": [],
   "source": [
    "base = base.fillna(value = valores)"
   ]
  },
  {
   "cell_type": "code",
   "execution_count": 20,
   "metadata": {},
   "outputs": [],
   "source": [
    "previsores = base.iloc[:, 1:13].values\n",
    "preco_real = base.iloc[:, 0].values"
   ]
  },
  {
   "cell_type": "code",
   "execution_count": 21,
   "metadata": {},
   "outputs": [],
   "source": [
    "from sklearn.preprocessing import LabelEncoder, OneHotEncoder\n",
    "from sklearn.compose import ColumnTransformer\n",
    "labelencoder_previsores = LabelEncoder()\n",
    "previsores[:, 0] = labelencoder_previsores.fit_transform(previsores[:, 0])\n",
    "previsores[:, 1] = labelencoder_previsores.fit_transform(previsores[:, 1])\n",
    "previsores[:, 3] = labelencoder_previsores.fit_transform(previsores[:, 3])\n",
    "previsores[:, 5] = labelencoder_previsores.fit_transform(previsores[:, 5])\n",
    "previsores[:, 8] = labelencoder_previsores.fit_transform(previsores[:, 8])\n",
    "previsores[:, 9] = labelencoder_previsores.fit_transform(previsores[:, 9])\n",
    "previsores[:, 10] = labelencoder_previsores.fit_transform(previsores[:, 10])"
   ]
  },
  {
   "cell_type": "code",
   "execution_count": 22,
   "metadata": {},
   "outputs": [],
   "source": [
    "categorical_columns = [0, 1, 3, 5, 8, 9, 10]\n",
    "onehotencoder = ct = ColumnTransformer(\n",
    "    [('one_hot_encoder', OneHotEncoder(), categorical_columns)],\n",
    "    remainder='passthrough')\n",
    "data_transformed = ct.fit_transform(previsores).toarray()"
   ]
  },
  {
   "cell_type": "code",
   "execution_count": 23,
   "metadata": {},
   "outputs": [],
   "source": [
    "def criarRede():\n",
    "    regressor = Sequential()\n",
    "    regressor.add(Dense(units = 158, activation = 'relu', input_dim = 316))\n",
    "    regressor.add(Dense(units = 158, activation = 'relu'))\n",
    "    regressor.add(Dense(units = 1, activation = 'linear'))\n",
    "    regressor.compile(loss = 'mean_absolute_error', optimizer = 'adam', metrics = ['mean_about_error'])\n",
    "    return regressor"
   ]
  },
  {
   "cell_type": "code",
   "execution_count": 24,
   "metadata": {},
   "outputs": [],
   "source": [
    "regressor = KerasRegressor(build_fn= criarRede, \n",
    "                           epochs = 100,\n",
    "                           batch_size = 300)"
   ]
  },
  {
   "cell_type": "code",
   "execution_count": 27,
   "metadata": {},
   "outputs": [
    {
     "name": "stdout",
     "output_type": "stream",
     "text": [
      "Epoch 1/100\n"
     ]
    },
    {
     "name": "stderr",
     "output_type": "stream",
     "text": [
      "c:\\Users\\samue\\AppData\\Local\\Programs\\Python\\Python312\\Lib\\site-packages\\scikeras\\wrappers.py:925: UserWarning: ``build_fn`` will be renamed to ``model`` in a future release, at which point use of ``build_fn`` will raise an Error instead.\n",
      "  X, y = self._initialize(X, y)\n",
      "c:\\Users\\samue\\AppData\\Local\\Programs\\Python\\Python312\\Lib\\site-packages\\keras\\src\\layers\\core\\dense.py:87: UserWarning: Do not pass an `input_shape`/`input_dim` argument to a layer. When using Sequential models, prefer using an `Input(shape)` object as the first layer in the model instead.\n",
      "  super().__init__(activity_regularizer=activity_regularizer, **kwargs)\n"
     ]
    },
    {
     "name": "stdout",
     "output_type": "stream",
     "text": [
      "Epoch 1/100\n"
     ]
    },
    {
     "name": "stderr",
     "output_type": "stream",
     "text": [
      "c:\\Users\\samue\\AppData\\Local\\Programs\\Python\\Python312\\Lib\\site-packages\\scikeras\\wrappers.py:925: UserWarning: ``build_fn`` will be renamed to ``model`` in a future release, at which point use of ``build_fn`` will raise an Error instead.\n",
      "  X, y = self._initialize(X, y)\n",
      "c:\\Users\\samue\\AppData\\Local\\Programs\\Python\\Python312\\Lib\\site-packages\\keras\\src\\layers\\core\\dense.py:87: UserWarning: Do not pass an `input_shape`/`input_dim` argument to a layer. When using Sequential models, prefer using an `Input(shape)` object as the first layer in the model instead.\n",
      "  super().__init__(activity_regularizer=activity_regularizer, **kwargs)\n"
     ]
    },
    {
     "name": "stdout",
     "output_type": "stream",
     "text": [
      "Epoch 1/100\n"
     ]
    },
    {
     "name": "stderr",
     "output_type": "stream",
     "text": [
      "c:\\Users\\samue\\AppData\\Local\\Programs\\Python\\Python312\\Lib\\site-packages\\scikeras\\wrappers.py:925: UserWarning: ``build_fn`` will be renamed to ``model`` in a future release, at which point use of ``build_fn`` will raise an Error instead.\n",
      "  X, y = self._initialize(X, y)\n",
      "c:\\Users\\samue\\AppData\\Local\\Programs\\Python\\Python312\\Lib\\site-packages\\keras\\src\\layers\\core\\dense.py:87: UserWarning: Do not pass an `input_shape`/`input_dim` argument to a layer. When using Sequential models, prefer using an `Input(shape)` object as the first layer in the model instead.\n",
      "  super().__init__(activity_regularizer=activity_regularizer, **kwargs)\n"
     ]
    },
    {
     "name": "stdout",
     "output_type": "stream",
     "text": [
      "Epoch 1/100\n"
     ]
    },
    {
     "name": "stderr",
     "output_type": "stream",
     "text": [
      "c:\\Users\\samue\\AppData\\Local\\Programs\\Python\\Python312\\Lib\\site-packages\\scikeras\\wrappers.py:925: UserWarning: ``build_fn`` will be renamed to ``model`` in a future release, at which point use of ``build_fn`` will raise an Error instead.\n",
      "  X, y = self._initialize(X, y)\n",
      "c:\\Users\\samue\\AppData\\Local\\Programs\\Python\\Python312\\Lib\\site-packages\\keras\\src\\layers\\core\\dense.py:87: UserWarning: Do not pass an `input_shape`/`input_dim` argument to a layer. When using Sequential models, prefer using an `Input(shape)` object as the first layer in the model instead.\n",
      "  super().__init__(activity_regularizer=activity_regularizer, **kwargs)\n"
     ]
    },
    {
     "name": "stdout",
     "output_type": "stream",
     "text": [
      "Epoch 1/100\n"
     ]
    },
    {
     "name": "stderr",
     "output_type": "stream",
     "text": [
      "c:\\Users\\samue\\AppData\\Local\\Programs\\Python\\Python312\\Lib\\site-packages\\scikeras\\wrappers.py:925: UserWarning: ``build_fn`` will be renamed to ``model`` in a future release, at which point use of ``build_fn`` will raise an Error instead.\n",
      "  X, y = self._initialize(X, y)\n",
      "c:\\Users\\samue\\AppData\\Local\\Programs\\Python\\Python312\\Lib\\site-packages\\keras\\src\\layers\\core\\dense.py:87: UserWarning: Do not pass an `input_shape`/`input_dim` argument to a layer. When using Sequential models, prefer using an `Input(shape)` object as the first layer in the model instead.\n",
      "  super().__init__(activity_regularizer=activity_regularizer, **kwargs)\n"
     ]
    },
    {
     "name": "stdout",
     "output_type": "stream",
     "text": [
      "Epoch 1/100\n"
     ]
    },
    {
     "name": "stderr",
     "output_type": "stream",
     "text": [
      "c:\\Users\\samue\\AppData\\Local\\Programs\\Python\\Python312\\Lib\\site-packages\\scikeras\\wrappers.py:925: UserWarning: ``build_fn`` will be renamed to ``model`` in a future release, at which point use of ``build_fn`` will raise an Error instead.\n",
      "  X, y = self._initialize(X, y)\n",
      "c:\\Users\\samue\\AppData\\Local\\Programs\\Python\\Python312\\Lib\\site-packages\\keras\\src\\layers\\core\\dense.py:87: UserWarning: Do not pass an `input_shape`/`input_dim` argument to a layer. When using Sequential models, prefer using an `Input(shape)` object as the first layer in the model instead.\n",
      "  super().__init__(activity_regularizer=activity_regularizer, **kwargs)\n"
     ]
    },
    {
     "name": "stdout",
     "output_type": "stream",
     "text": [
      "Epoch 1/100\n"
     ]
    },
    {
     "name": "stderr",
     "output_type": "stream",
     "text": [
      "c:\\Users\\samue\\AppData\\Local\\Programs\\Python\\Python312\\Lib\\site-packages\\scikeras\\wrappers.py:925: UserWarning: ``build_fn`` will be renamed to ``model`` in a future release, at which point use of ``build_fn`` will raise an Error instead.\n",
      "  X, y = self._initialize(X, y)\n",
      "c:\\Users\\samue\\AppData\\Local\\Programs\\Python\\Python312\\Lib\\site-packages\\keras\\src\\layers\\core\\dense.py:87: UserWarning: Do not pass an `input_shape`/`input_dim` argument to a layer. When using Sequential models, prefer using an `Input(shape)` object as the first layer in the model instead.\n",
      "  super().__init__(activity_regularizer=activity_regularizer, **kwargs)\n"
     ]
    },
    {
     "name": "stdout",
     "output_type": "stream",
     "text": [
      "Epoch 1/100\n"
     ]
    },
    {
     "name": "stderr",
     "output_type": "stream",
     "text": [
      "c:\\Users\\samue\\AppData\\Local\\Programs\\Python\\Python312\\Lib\\site-packages\\scikeras\\wrappers.py:925: UserWarning: ``build_fn`` will be renamed to ``model`` in a future release, at which point use of ``build_fn`` will raise an Error instead.\n",
      "  X, y = self._initialize(X, y)\n",
      "c:\\Users\\samue\\AppData\\Local\\Programs\\Python\\Python312\\Lib\\site-packages\\keras\\src\\layers\\core\\dense.py:87: UserWarning: Do not pass an `input_shape`/`input_dim` argument to a layer. When using Sequential models, prefer using an `Input(shape)` object as the first layer in the model instead.\n",
      "  super().__init__(activity_regularizer=activity_regularizer, **kwargs)\n"
     ]
    },
    {
     "name": "stdout",
     "output_type": "stream",
     "text": [
      "Epoch 1/100\n"
     ]
    },
    {
     "name": "stderr",
     "output_type": "stream",
     "text": [
      "c:\\Users\\samue\\AppData\\Local\\Programs\\Python\\Python312\\Lib\\site-packages\\scikeras\\wrappers.py:925: UserWarning: ``build_fn`` will be renamed to ``model`` in a future release, at which point use of ``build_fn`` will raise an Error instead.\n",
      "  X, y = self._initialize(X, y)\n",
      "c:\\Users\\samue\\AppData\\Local\\Programs\\Python\\Python312\\Lib\\site-packages\\keras\\src\\layers\\core\\dense.py:87: UserWarning: Do not pass an `input_shape`/`input_dim` argument to a layer. When using Sequential models, prefer using an `Input(shape)` object as the first layer in the model instead.\n",
      "  super().__init__(activity_regularizer=activity_regularizer, **kwargs)\n"
     ]
    },
    {
     "name": "stdout",
     "output_type": "stream",
     "text": [
      "Epoch 1/100\n"
     ]
    },
    {
     "name": "stderr",
     "output_type": "stream",
     "text": [
      "c:\\Users\\samue\\AppData\\Local\\Programs\\Python\\Python312\\Lib\\site-packages\\scikeras\\wrappers.py:925: UserWarning: ``build_fn`` will be renamed to ``model`` in a future release, at which point use of ``build_fn`` will raise an Error instead.\n",
      "  X, y = self._initialize(X, y)\n",
      "c:\\Users\\samue\\AppData\\Local\\Programs\\Python\\Python312\\Lib\\site-packages\\keras\\src\\layers\\core\\dense.py:87: UserWarning: Do not pass an `input_shape`/`input_dim` argument to a layer. When using Sequential models, prefer using an `Input(shape)` object as the first layer in the model instead.\n",
      "  super().__init__(activity_regularizer=activity_regularizer, **kwargs)\n"
     ]
    },
    {
     "ename": "ValueError",
     "evalue": "\nAll the 10 fits failed.\nIt is very likely that your model is misconfigured.\nYou can try to debug the error by setting error_score='raise'.\n\nBelow are more details about the failures:\n--------------------------------------------------------------------------------\n1 fits failed with the following error:\nTraceback (most recent call last):\n  File \"c:\\Users\\samue\\AppData\\Local\\Programs\\Python\\Python312\\Lib\\site-packages\\sklearn\\model_selection\\_validation.py\", line 895, in _fit_and_score\n    estimator.fit(X_train, y_train, **fit_params)\n  File \"c:\\Users\\samue\\AppData\\Local\\Programs\\Python\\Python312\\Lib\\site-packages\\scikeras\\wrappers.py\", line 770, in fit\n    self._fit(\n  File \"c:\\Users\\samue\\AppData\\Local\\Programs\\Python\\Python312\\Lib\\site-packages\\scikeras\\wrappers.py\", line 938, in _fit\n    self._fit_keras_model(\n  File \"c:\\Users\\samue\\AppData\\Local\\Programs\\Python\\Python312\\Lib\\site-packages\\scikeras\\wrappers.py\", line 535, in _fit_keras_model\n    hist = self.model_.fit(x=X, y=y, **fit_args)\n           ^^^^^^^^^^^^^^^^^^^^^^^^^^^^^^^^^^^^^\n  File \"c:\\Users\\samue\\AppData\\Local\\Programs\\Python\\Python312\\Lib\\site-packages\\keras\\src\\utils\\traceback_utils.py\", line 122, in error_handler\n    raise e.with_traceback(filtered_tb) from None\n  File \"c:\\Users\\samue\\AppData\\Local\\Programs\\Python\\Python312\\Lib\\site-packages\\keras\\src\\layers\\input_spec.py\", line 227, in assert_input_compatibility\n    raise ValueError(\nValueError: Exception encountered when calling Sequential.call().\n\n\u001b[1mInput 0 of layer \"dense_180\" is incompatible with the layer: expected axis -1 of input shape to have value 316, but received input with shape (None, 11)\u001b[0m\n\nArguments received by Sequential.call():\n  • inputs=tf.Tensor(shape=(None, 11), dtype=float32)\n  • training=True\n  • mask=None\n\n--------------------------------------------------------------------------------\n1 fits failed with the following error:\nTraceback (most recent call last):\n  File \"c:\\Users\\samue\\AppData\\Local\\Programs\\Python\\Python312\\Lib\\site-packages\\sklearn\\model_selection\\_validation.py\", line 895, in _fit_and_score\n    estimator.fit(X_train, y_train, **fit_params)\n  File \"c:\\Users\\samue\\AppData\\Local\\Programs\\Python\\Python312\\Lib\\site-packages\\scikeras\\wrappers.py\", line 770, in fit\n    self._fit(\n  File \"c:\\Users\\samue\\AppData\\Local\\Programs\\Python\\Python312\\Lib\\site-packages\\scikeras\\wrappers.py\", line 938, in _fit\n    self._fit_keras_model(\n  File \"c:\\Users\\samue\\AppData\\Local\\Programs\\Python\\Python312\\Lib\\site-packages\\scikeras\\wrappers.py\", line 535, in _fit_keras_model\n    hist = self.model_.fit(x=X, y=y, **fit_args)\n           ^^^^^^^^^^^^^^^^^^^^^^^^^^^^^^^^^^^^^\n  File \"c:\\Users\\samue\\AppData\\Local\\Programs\\Python\\Python312\\Lib\\site-packages\\keras\\src\\utils\\traceback_utils.py\", line 122, in error_handler\n    raise e.with_traceback(filtered_tb) from None\n  File \"c:\\Users\\samue\\AppData\\Local\\Programs\\Python\\Python312\\Lib\\site-packages\\keras\\src\\layers\\input_spec.py\", line 227, in assert_input_compatibility\n    raise ValueError(\nValueError: Exception encountered when calling Sequential.call().\n\n\u001b[1mInput 0 of layer \"dense_183\" is incompatible with the layer: expected axis -1 of input shape to have value 316, but received input with shape (None, 11)\u001b[0m\n\nArguments received by Sequential.call():\n  • inputs=tf.Tensor(shape=(None, 11), dtype=float32)\n  • training=True\n  • mask=None\n\n--------------------------------------------------------------------------------\n1 fits failed with the following error:\nTraceback (most recent call last):\n  File \"c:\\Users\\samue\\AppData\\Local\\Programs\\Python\\Python312\\Lib\\site-packages\\sklearn\\model_selection\\_validation.py\", line 895, in _fit_and_score\n    estimator.fit(X_train, y_train, **fit_params)\n  File \"c:\\Users\\samue\\AppData\\Local\\Programs\\Python\\Python312\\Lib\\site-packages\\scikeras\\wrappers.py\", line 770, in fit\n    self._fit(\n  File \"c:\\Users\\samue\\AppData\\Local\\Programs\\Python\\Python312\\Lib\\site-packages\\scikeras\\wrappers.py\", line 938, in _fit\n    self._fit_keras_model(\n  File \"c:\\Users\\samue\\AppData\\Local\\Programs\\Python\\Python312\\Lib\\site-packages\\scikeras\\wrappers.py\", line 535, in _fit_keras_model\n    hist = self.model_.fit(x=X, y=y, **fit_args)\n           ^^^^^^^^^^^^^^^^^^^^^^^^^^^^^^^^^^^^^\n  File \"c:\\Users\\samue\\AppData\\Local\\Programs\\Python\\Python312\\Lib\\site-packages\\keras\\src\\utils\\traceback_utils.py\", line 122, in error_handler\n    raise e.with_traceback(filtered_tb) from None\n  File \"c:\\Users\\samue\\AppData\\Local\\Programs\\Python\\Python312\\Lib\\site-packages\\keras\\src\\layers\\input_spec.py\", line 227, in assert_input_compatibility\n    raise ValueError(\nValueError: Exception encountered when calling Sequential.call().\n\n\u001b[1mInput 0 of layer \"dense_186\" is incompatible with the layer: expected axis -1 of input shape to have value 316, but received input with shape (None, 11)\u001b[0m\n\nArguments received by Sequential.call():\n  • inputs=tf.Tensor(shape=(None, 11), dtype=float32)\n  • training=True\n  • mask=None\n\n--------------------------------------------------------------------------------\n1 fits failed with the following error:\nTraceback (most recent call last):\n  File \"c:\\Users\\samue\\AppData\\Local\\Programs\\Python\\Python312\\Lib\\site-packages\\sklearn\\model_selection\\_validation.py\", line 895, in _fit_and_score\n    estimator.fit(X_train, y_train, **fit_params)\n  File \"c:\\Users\\samue\\AppData\\Local\\Programs\\Python\\Python312\\Lib\\site-packages\\scikeras\\wrappers.py\", line 770, in fit\n    self._fit(\n  File \"c:\\Users\\samue\\AppData\\Local\\Programs\\Python\\Python312\\Lib\\site-packages\\scikeras\\wrappers.py\", line 938, in _fit\n    self._fit_keras_model(\n  File \"c:\\Users\\samue\\AppData\\Local\\Programs\\Python\\Python312\\Lib\\site-packages\\scikeras\\wrappers.py\", line 535, in _fit_keras_model\n    hist = self.model_.fit(x=X, y=y, **fit_args)\n           ^^^^^^^^^^^^^^^^^^^^^^^^^^^^^^^^^^^^^\n  File \"c:\\Users\\samue\\AppData\\Local\\Programs\\Python\\Python312\\Lib\\site-packages\\keras\\src\\utils\\traceback_utils.py\", line 122, in error_handler\n    raise e.with_traceback(filtered_tb) from None\n  File \"c:\\Users\\samue\\AppData\\Local\\Programs\\Python\\Python312\\Lib\\site-packages\\keras\\src\\layers\\input_spec.py\", line 227, in assert_input_compatibility\n    raise ValueError(\nValueError: Exception encountered when calling Sequential.call().\n\n\u001b[1mInput 0 of layer \"dense_189\" is incompatible with the layer: expected axis -1 of input shape to have value 316, but received input with shape (None, 11)\u001b[0m\n\nArguments received by Sequential.call():\n  • inputs=tf.Tensor(shape=(None, 11), dtype=float32)\n  • training=True\n  • mask=None\n\n--------------------------------------------------------------------------------\n1 fits failed with the following error:\nTraceback (most recent call last):\n  File \"c:\\Users\\samue\\AppData\\Local\\Programs\\Python\\Python312\\Lib\\site-packages\\sklearn\\model_selection\\_validation.py\", line 895, in _fit_and_score\n    estimator.fit(X_train, y_train, **fit_params)\n  File \"c:\\Users\\samue\\AppData\\Local\\Programs\\Python\\Python312\\Lib\\site-packages\\scikeras\\wrappers.py\", line 770, in fit\n    self._fit(\n  File \"c:\\Users\\samue\\AppData\\Local\\Programs\\Python\\Python312\\Lib\\site-packages\\scikeras\\wrappers.py\", line 938, in _fit\n    self._fit_keras_model(\n  File \"c:\\Users\\samue\\AppData\\Local\\Programs\\Python\\Python312\\Lib\\site-packages\\scikeras\\wrappers.py\", line 535, in _fit_keras_model\n    hist = self.model_.fit(x=X, y=y, **fit_args)\n           ^^^^^^^^^^^^^^^^^^^^^^^^^^^^^^^^^^^^^\n  File \"c:\\Users\\samue\\AppData\\Local\\Programs\\Python\\Python312\\Lib\\site-packages\\keras\\src\\utils\\traceback_utils.py\", line 122, in error_handler\n    raise e.with_traceback(filtered_tb) from None\n  File \"c:\\Users\\samue\\AppData\\Local\\Programs\\Python\\Python312\\Lib\\site-packages\\keras\\src\\layers\\input_spec.py\", line 227, in assert_input_compatibility\n    raise ValueError(\nValueError: Exception encountered when calling Sequential.call().\n\n\u001b[1mInput 0 of layer \"dense_192\" is incompatible with the layer: expected axis -1 of input shape to have value 316, but received input with shape (None, 11)\u001b[0m\n\nArguments received by Sequential.call():\n  • inputs=tf.Tensor(shape=(None, 11), dtype=float32)\n  • training=True\n  • mask=None\n\n--------------------------------------------------------------------------------\n1 fits failed with the following error:\nTraceback (most recent call last):\n  File \"c:\\Users\\samue\\AppData\\Local\\Programs\\Python\\Python312\\Lib\\site-packages\\sklearn\\model_selection\\_validation.py\", line 895, in _fit_and_score\n    estimator.fit(X_train, y_train, **fit_params)\n  File \"c:\\Users\\samue\\AppData\\Local\\Programs\\Python\\Python312\\Lib\\site-packages\\scikeras\\wrappers.py\", line 770, in fit\n    self._fit(\n  File \"c:\\Users\\samue\\AppData\\Local\\Programs\\Python\\Python312\\Lib\\site-packages\\scikeras\\wrappers.py\", line 938, in _fit\n    self._fit_keras_model(\n  File \"c:\\Users\\samue\\AppData\\Local\\Programs\\Python\\Python312\\Lib\\site-packages\\scikeras\\wrappers.py\", line 535, in _fit_keras_model\n    hist = self.model_.fit(x=X, y=y, **fit_args)\n           ^^^^^^^^^^^^^^^^^^^^^^^^^^^^^^^^^^^^^\n  File \"c:\\Users\\samue\\AppData\\Local\\Programs\\Python\\Python312\\Lib\\site-packages\\keras\\src\\utils\\traceback_utils.py\", line 122, in error_handler\n    raise e.with_traceback(filtered_tb) from None\n  File \"c:\\Users\\samue\\AppData\\Local\\Programs\\Python\\Python312\\Lib\\site-packages\\keras\\src\\layers\\input_spec.py\", line 227, in assert_input_compatibility\n    raise ValueError(\nValueError: Exception encountered when calling Sequential.call().\n\n\u001b[1mInput 0 of layer \"dense_195\" is incompatible with the layer: expected axis -1 of input shape to have value 316, but received input with shape (None, 11)\u001b[0m\n\nArguments received by Sequential.call():\n  • inputs=tf.Tensor(shape=(None, 11), dtype=float32)\n  • training=True\n  • mask=None\n\n--------------------------------------------------------------------------------\n1 fits failed with the following error:\nTraceback (most recent call last):\n  File \"c:\\Users\\samue\\AppData\\Local\\Programs\\Python\\Python312\\Lib\\site-packages\\sklearn\\model_selection\\_validation.py\", line 895, in _fit_and_score\n    estimator.fit(X_train, y_train, **fit_params)\n  File \"c:\\Users\\samue\\AppData\\Local\\Programs\\Python\\Python312\\Lib\\site-packages\\scikeras\\wrappers.py\", line 770, in fit\n    self._fit(\n  File \"c:\\Users\\samue\\AppData\\Local\\Programs\\Python\\Python312\\Lib\\site-packages\\scikeras\\wrappers.py\", line 938, in _fit\n    self._fit_keras_model(\n  File \"c:\\Users\\samue\\AppData\\Local\\Programs\\Python\\Python312\\Lib\\site-packages\\scikeras\\wrappers.py\", line 535, in _fit_keras_model\n    hist = self.model_.fit(x=X, y=y, **fit_args)\n           ^^^^^^^^^^^^^^^^^^^^^^^^^^^^^^^^^^^^^\n  File \"c:\\Users\\samue\\AppData\\Local\\Programs\\Python\\Python312\\Lib\\site-packages\\keras\\src\\utils\\traceback_utils.py\", line 122, in error_handler\n    raise e.with_traceback(filtered_tb) from None\n  File \"c:\\Users\\samue\\AppData\\Local\\Programs\\Python\\Python312\\Lib\\site-packages\\keras\\src\\layers\\input_spec.py\", line 227, in assert_input_compatibility\n    raise ValueError(\nValueError: Exception encountered when calling Sequential.call().\n\n\u001b[1mInput 0 of layer \"dense_198\" is incompatible with the layer: expected axis -1 of input shape to have value 316, but received input with shape (None, 11)\u001b[0m\n\nArguments received by Sequential.call():\n  • inputs=tf.Tensor(shape=(None, 11), dtype=float32)\n  • training=True\n  • mask=None\n\n--------------------------------------------------------------------------------\n1 fits failed with the following error:\nTraceback (most recent call last):\n  File \"c:\\Users\\samue\\AppData\\Local\\Programs\\Python\\Python312\\Lib\\site-packages\\sklearn\\model_selection\\_validation.py\", line 895, in _fit_and_score\n    estimator.fit(X_train, y_train, **fit_params)\n  File \"c:\\Users\\samue\\AppData\\Local\\Programs\\Python\\Python312\\Lib\\site-packages\\scikeras\\wrappers.py\", line 770, in fit\n    self._fit(\n  File \"c:\\Users\\samue\\AppData\\Local\\Programs\\Python\\Python312\\Lib\\site-packages\\scikeras\\wrappers.py\", line 938, in _fit\n    self._fit_keras_model(\n  File \"c:\\Users\\samue\\AppData\\Local\\Programs\\Python\\Python312\\Lib\\site-packages\\scikeras\\wrappers.py\", line 535, in _fit_keras_model\n    hist = self.model_.fit(x=X, y=y, **fit_args)\n           ^^^^^^^^^^^^^^^^^^^^^^^^^^^^^^^^^^^^^\n  File \"c:\\Users\\samue\\AppData\\Local\\Programs\\Python\\Python312\\Lib\\site-packages\\keras\\src\\utils\\traceback_utils.py\", line 122, in error_handler\n    raise e.with_traceback(filtered_tb) from None\n  File \"c:\\Users\\samue\\AppData\\Local\\Programs\\Python\\Python312\\Lib\\site-packages\\keras\\src\\layers\\input_spec.py\", line 227, in assert_input_compatibility\n    raise ValueError(\nValueError: Exception encountered when calling Sequential.call().\n\n\u001b[1mInput 0 of layer \"dense_201\" is incompatible with the layer: expected axis -1 of input shape to have value 316, but received input with shape (None, 11)\u001b[0m\n\nArguments received by Sequential.call():\n  • inputs=tf.Tensor(shape=(None, 11), dtype=float32)\n  • training=True\n  • mask=None\n\n--------------------------------------------------------------------------------\n1 fits failed with the following error:\nTraceback (most recent call last):\n  File \"c:\\Users\\samue\\AppData\\Local\\Programs\\Python\\Python312\\Lib\\site-packages\\sklearn\\model_selection\\_validation.py\", line 895, in _fit_and_score\n    estimator.fit(X_train, y_train, **fit_params)\n  File \"c:\\Users\\samue\\AppData\\Local\\Programs\\Python\\Python312\\Lib\\site-packages\\scikeras\\wrappers.py\", line 770, in fit\n    self._fit(\n  File \"c:\\Users\\samue\\AppData\\Local\\Programs\\Python\\Python312\\Lib\\site-packages\\scikeras\\wrappers.py\", line 938, in _fit\n    self._fit_keras_model(\n  File \"c:\\Users\\samue\\AppData\\Local\\Programs\\Python\\Python312\\Lib\\site-packages\\scikeras\\wrappers.py\", line 535, in _fit_keras_model\n    hist = self.model_.fit(x=X, y=y, **fit_args)\n           ^^^^^^^^^^^^^^^^^^^^^^^^^^^^^^^^^^^^^\n  File \"c:\\Users\\samue\\AppData\\Local\\Programs\\Python\\Python312\\Lib\\site-packages\\keras\\src\\utils\\traceback_utils.py\", line 122, in error_handler\n    raise e.with_traceback(filtered_tb) from None\n  File \"c:\\Users\\samue\\AppData\\Local\\Programs\\Python\\Python312\\Lib\\site-packages\\keras\\src\\layers\\input_spec.py\", line 227, in assert_input_compatibility\n    raise ValueError(\nValueError: Exception encountered when calling Sequential.call().\n\n\u001b[1mInput 0 of layer \"dense_204\" is incompatible with the layer: expected axis -1 of input shape to have value 316, but received input with shape (None, 11)\u001b[0m\n\nArguments received by Sequential.call():\n  • inputs=tf.Tensor(shape=(None, 11), dtype=float32)\n  • training=True\n  • mask=None\n\n--------------------------------------------------------------------------------\n1 fits failed with the following error:\nTraceback (most recent call last):\n  File \"c:\\Users\\samue\\AppData\\Local\\Programs\\Python\\Python312\\Lib\\site-packages\\sklearn\\model_selection\\_validation.py\", line 895, in _fit_and_score\n    estimator.fit(X_train, y_train, **fit_params)\n  File \"c:\\Users\\samue\\AppData\\Local\\Programs\\Python\\Python312\\Lib\\site-packages\\scikeras\\wrappers.py\", line 770, in fit\n    self._fit(\n  File \"c:\\Users\\samue\\AppData\\Local\\Programs\\Python\\Python312\\Lib\\site-packages\\scikeras\\wrappers.py\", line 938, in _fit\n    self._fit_keras_model(\n  File \"c:\\Users\\samue\\AppData\\Local\\Programs\\Python\\Python312\\Lib\\site-packages\\scikeras\\wrappers.py\", line 535, in _fit_keras_model\n    hist = self.model_.fit(x=X, y=y, **fit_args)\n           ^^^^^^^^^^^^^^^^^^^^^^^^^^^^^^^^^^^^^\n  File \"c:\\Users\\samue\\AppData\\Local\\Programs\\Python\\Python312\\Lib\\site-packages\\keras\\src\\utils\\traceback_utils.py\", line 122, in error_handler\n    raise e.with_traceback(filtered_tb) from None\n  File \"c:\\Users\\samue\\AppData\\Local\\Programs\\Python\\Python312\\Lib\\site-packages\\keras\\src\\layers\\input_spec.py\", line 227, in assert_input_compatibility\n    raise ValueError(\nValueError: Exception encountered when calling Sequential.call().\n\n\u001b[1mInput 0 of layer \"dense_207\" is incompatible with the layer: expected axis -1 of input shape to have value 316, but received input with shape (None, 11)\u001b[0m\n\nArguments received by Sequential.call():\n  • inputs=tf.Tensor(shape=(None, 11), dtype=float32)\n  • training=True\n  • mask=None\n",
     "output_type": "error",
     "traceback": [
      "\u001b[1;31m---------------------------------------------------------------------------\u001b[0m",
      "\u001b[1;31mValueError\u001b[0m                                Traceback (most recent call last)",
      "Cell \u001b[1;32mIn[27], line 1\u001b[0m\n\u001b[1;32m----> 1\u001b[0m resultados \u001b[38;5;241m=\u001b[39m \u001b[43mcross_val_score\u001b[49m\u001b[43m(\u001b[49m\u001b[43mestimator\u001b[49m\u001b[38;5;241;43m=\u001b[39;49m\u001b[43mregressor\u001b[49m\u001b[43m,\u001b[49m\u001b[43m \u001b[49m\u001b[43mX\u001b[49m\u001b[38;5;241;43m=\u001b[39;49m\u001b[43mprevisores\u001b[49m\u001b[43m,\u001b[49m\u001b[43m \u001b[49m\u001b[43my\u001b[49m\u001b[38;5;241;43m=\u001b[39;49m\u001b[43mpreco_real\u001b[49m\u001b[43m,\u001b[49m\u001b[43m \u001b[49m\u001b[43mcv\u001b[49m\u001b[38;5;241;43m=\u001b[39;49m\u001b[38;5;241;43m10\u001b[39;49m\u001b[43m,\u001b[49m\u001b[43m \u001b[49m\u001b[43mscoring\u001b[49m\u001b[38;5;241;43m=\u001b[39;49m\u001b[38;5;124;43m'\u001b[39;49m\u001b[38;5;124;43mneg_mean_absolute_error\u001b[39;49m\u001b[38;5;124;43m'\u001b[39;49m\u001b[43m)\u001b[49m\n",
      "File \u001b[1;32mc:\\Users\\samue\\AppData\\Local\\Programs\\Python\\Python312\\Lib\\site-packages\\sklearn\\utils\\_param_validation.py:213\u001b[0m, in \u001b[0;36mvalidate_params.<locals>.decorator.<locals>.wrapper\u001b[1;34m(*args, **kwargs)\u001b[0m\n\u001b[0;32m    207\u001b[0m \u001b[38;5;28;01mtry\u001b[39;00m:\n\u001b[0;32m    208\u001b[0m     \u001b[38;5;28;01mwith\u001b[39;00m config_context(\n\u001b[0;32m    209\u001b[0m         skip_parameter_validation\u001b[38;5;241m=\u001b[39m(\n\u001b[0;32m    210\u001b[0m             prefer_skip_nested_validation \u001b[38;5;129;01mor\u001b[39;00m global_skip_validation\n\u001b[0;32m    211\u001b[0m         )\n\u001b[0;32m    212\u001b[0m     ):\n\u001b[1;32m--> 213\u001b[0m         \u001b[38;5;28;01mreturn\u001b[39;00m \u001b[43mfunc\u001b[49m\u001b[43m(\u001b[49m\u001b[38;5;241;43m*\u001b[39;49m\u001b[43margs\u001b[49m\u001b[43m,\u001b[49m\u001b[43m \u001b[49m\u001b[38;5;241;43m*\u001b[39;49m\u001b[38;5;241;43m*\u001b[39;49m\u001b[43mkwargs\u001b[49m\u001b[43m)\u001b[49m\n\u001b[0;32m    214\u001b[0m \u001b[38;5;28;01mexcept\u001b[39;00m InvalidParameterError \u001b[38;5;28;01mas\u001b[39;00m e:\n\u001b[0;32m    215\u001b[0m     \u001b[38;5;66;03m# When the function is just a wrapper around an estimator, we allow\u001b[39;00m\n\u001b[0;32m    216\u001b[0m     \u001b[38;5;66;03m# the function to delegate validation to the estimator, but we replace\u001b[39;00m\n\u001b[0;32m    217\u001b[0m     \u001b[38;5;66;03m# the name of the estimator by the name of the function in the error\u001b[39;00m\n\u001b[0;32m    218\u001b[0m     \u001b[38;5;66;03m# message to avoid confusion.\u001b[39;00m\n\u001b[0;32m    219\u001b[0m     msg \u001b[38;5;241m=\u001b[39m re\u001b[38;5;241m.\u001b[39msub(\n\u001b[0;32m    220\u001b[0m         \u001b[38;5;124mr\u001b[39m\u001b[38;5;124m\"\u001b[39m\u001b[38;5;124mparameter of \u001b[39m\u001b[38;5;124m\\\u001b[39m\u001b[38;5;124mw+ must be\u001b[39m\u001b[38;5;124m\"\u001b[39m,\n\u001b[0;32m    221\u001b[0m         \u001b[38;5;124mf\u001b[39m\u001b[38;5;124m\"\u001b[39m\u001b[38;5;124mparameter of \u001b[39m\u001b[38;5;132;01m{\u001b[39;00mfunc\u001b[38;5;241m.\u001b[39m\u001b[38;5;18m__qualname__\u001b[39m\u001b[38;5;132;01m}\u001b[39;00m\u001b[38;5;124m must be\u001b[39m\u001b[38;5;124m\"\u001b[39m,\n\u001b[0;32m    222\u001b[0m         \u001b[38;5;28mstr\u001b[39m(e),\n\u001b[0;32m    223\u001b[0m     )\n",
      "File \u001b[1;32mc:\\Users\\samue\\AppData\\Local\\Programs\\Python\\Python312\\Lib\\site-packages\\sklearn\\model_selection\\_validation.py:719\u001b[0m, in \u001b[0;36mcross_val_score\u001b[1;34m(estimator, X, y, groups, scoring, cv, n_jobs, verbose, fit_params, params, pre_dispatch, error_score)\u001b[0m\n\u001b[0;32m    716\u001b[0m \u001b[38;5;66;03m# To ensure multimetric format is not supported\u001b[39;00m\n\u001b[0;32m    717\u001b[0m scorer \u001b[38;5;241m=\u001b[39m check_scoring(estimator, scoring\u001b[38;5;241m=\u001b[39mscoring)\n\u001b[1;32m--> 719\u001b[0m cv_results \u001b[38;5;241m=\u001b[39m \u001b[43mcross_validate\u001b[49m\u001b[43m(\u001b[49m\n\u001b[0;32m    720\u001b[0m \u001b[43m    \u001b[49m\u001b[43mestimator\u001b[49m\u001b[38;5;241;43m=\u001b[39;49m\u001b[43mestimator\u001b[49m\u001b[43m,\u001b[49m\n\u001b[0;32m    721\u001b[0m \u001b[43m    \u001b[49m\u001b[43mX\u001b[49m\u001b[38;5;241;43m=\u001b[39;49m\u001b[43mX\u001b[49m\u001b[43m,\u001b[49m\n\u001b[0;32m    722\u001b[0m \u001b[43m    \u001b[49m\u001b[43my\u001b[49m\u001b[38;5;241;43m=\u001b[39;49m\u001b[43my\u001b[49m\u001b[43m,\u001b[49m\n\u001b[0;32m    723\u001b[0m \u001b[43m    \u001b[49m\u001b[43mgroups\u001b[49m\u001b[38;5;241;43m=\u001b[39;49m\u001b[43mgroups\u001b[49m\u001b[43m,\u001b[49m\n\u001b[0;32m    724\u001b[0m \u001b[43m    \u001b[49m\u001b[43mscoring\u001b[49m\u001b[38;5;241;43m=\u001b[39;49m\u001b[43m{\u001b[49m\u001b[38;5;124;43m\"\u001b[39;49m\u001b[38;5;124;43mscore\u001b[39;49m\u001b[38;5;124;43m\"\u001b[39;49m\u001b[43m:\u001b[49m\u001b[43m \u001b[49m\u001b[43mscorer\u001b[49m\u001b[43m}\u001b[49m\u001b[43m,\u001b[49m\n\u001b[0;32m    725\u001b[0m \u001b[43m    \u001b[49m\u001b[43mcv\u001b[49m\u001b[38;5;241;43m=\u001b[39;49m\u001b[43mcv\u001b[49m\u001b[43m,\u001b[49m\n\u001b[0;32m    726\u001b[0m \u001b[43m    \u001b[49m\u001b[43mn_jobs\u001b[49m\u001b[38;5;241;43m=\u001b[39;49m\u001b[43mn_jobs\u001b[49m\u001b[43m,\u001b[49m\n\u001b[0;32m    727\u001b[0m \u001b[43m    \u001b[49m\u001b[43mverbose\u001b[49m\u001b[38;5;241;43m=\u001b[39;49m\u001b[43mverbose\u001b[49m\u001b[43m,\u001b[49m\n\u001b[0;32m    728\u001b[0m \u001b[43m    \u001b[49m\u001b[43mfit_params\u001b[49m\u001b[38;5;241;43m=\u001b[39;49m\u001b[43mfit_params\u001b[49m\u001b[43m,\u001b[49m\n\u001b[0;32m    729\u001b[0m \u001b[43m    \u001b[49m\u001b[43mparams\u001b[49m\u001b[38;5;241;43m=\u001b[39;49m\u001b[43mparams\u001b[49m\u001b[43m,\u001b[49m\n\u001b[0;32m    730\u001b[0m \u001b[43m    \u001b[49m\u001b[43mpre_dispatch\u001b[49m\u001b[38;5;241;43m=\u001b[39;49m\u001b[43mpre_dispatch\u001b[49m\u001b[43m,\u001b[49m\n\u001b[0;32m    731\u001b[0m \u001b[43m    \u001b[49m\u001b[43merror_score\u001b[49m\u001b[38;5;241;43m=\u001b[39;49m\u001b[43merror_score\u001b[49m\u001b[43m,\u001b[49m\n\u001b[0;32m    732\u001b[0m \u001b[43m\u001b[49m\u001b[43m)\u001b[49m\n\u001b[0;32m    733\u001b[0m \u001b[38;5;28;01mreturn\u001b[39;00m cv_results[\u001b[38;5;124m\"\u001b[39m\u001b[38;5;124mtest_score\u001b[39m\u001b[38;5;124m\"\u001b[39m]\n",
      "File \u001b[1;32mc:\\Users\\samue\\AppData\\Local\\Programs\\Python\\Python312\\Lib\\site-packages\\sklearn\\utils\\_param_validation.py:213\u001b[0m, in \u001b[0;36mvalidate_params.<locals>.decorator.<locals>.wrapper\u001b[1;34m(*args, **kwargs)\u001b[0m\n\u001b[0;32m    207\u001b[0m \u001b[38;5;28;01mtry\u001b[39;00m:\n\u001b[0;32m    208\u001b[0m     \u001b[38;5;28;01mwith\u001b[39;00m config_context(\n\u001b[0;32m    209\u001b[0m         skip_parameter_validation\u001b[38;5;241m=\u001b[39m(\n\u001b[0;32m    210\u001b[0m             prefer_skip_nested_validation \u001b[38;5;129;01mor\u001b[39;00m global_skip_validation\n\u001b[0;32m    211\u001b[0m         )\n\u001b[0;32m    212\u001b[0m     ):\n\u001b[1;32m--> 213\u001b[0m         \u001b[38;5;28;01mreturn\u001b[39;00m \u001b[43mfunc\u001b[49m\u001b[43m(\u001b[49m\u001b[38;5;241;43m*\u001b[39;49m\u001b[43margs\u001b[49m\u001b[43m,\u001b[49m\u001b[43m \u001b[49m\u001b[38;5;241;43m*\u001b[39;49m\u001b[38;5;241;43m*\u001b[39;49m\u001b[43mkwargs\u001b[49m\u001b[43m)\u001b[49m\n\u001b[0;32m    214\u001b[0m \u001b[38;5;28;01mexcept\u001b[39;00m InvalidParameterError \u001b[38;5;28;01mas\u001b[39;00m e:\n\u001b[0;32m    215\u001b[0m     \u001b[38;5;66;03m# When the function is just a wrapper around an estimator, we allow\u001b[39;00m\n\u001b[0;32m    216\u001b[0m     \u001b[38;5;66;03m# the function to delegate validation to the estimator, but we replace\u001b[39;00m\n\u001b[0;32m    217\u001b[0m     \u001b[38;5;66;03m# the name of the estimator by the name of the function in the error\u001b[39;00m\n\u001b[0;32m    218\u001b[0m     \u001b[38;5;66;03m# message to avoid confusion.\u001b[39;00m\n\u001b[0;32m    219\u001b[0m     msg \u001b[38;5;241m=\u001b[39m re\u001b[38;5;241m.\u001b[39msub(\n\u001b[0;32m    220\u001b[0m         \u001b[38;5;124mr\u001b[39m\u001b[38;5;124m\"\u001b[39m\u001b[38;5;124mparameter of \u001b[39m\u001b[38;5;124m\\\u001b[39m\u001b[38;5;124mw+ must be\u001b[39m\u001b[38;5;124m\"\u001b[39m,\n\u001b[0;32m    221\u001b[0m         \u001b[38;5;124mf\u001b[39m\u001b[38;5;124m\"\u001b[39m\u001b[38;5;124mparameter of \u001b[39m\u001b[38;5;132;01m{\u001b[39;00mfunc\u001b[38;5;241m.\u001b[39m\u001b[38;5;18m__qualname__\u001b[39m\u001b[38;5;132;01m}\u001b[39;00m\u001b[38;5;124m must be\u001b[39m\u001b[38;5;124m\"\u001b[39m,\n\u001b[0;32m    222\u001b[0m         \u001b[38;5;28mstr\u001b[39m(e),\n\u001b[0;32m    223\u001b[0m     )\n",
      "File \u001b[1;32mc:\\Users\\samue\\AppData\\Local\\Programs\\Python\\Python312\\Lib\\site-packages\\sklearn\\model_selection\\_validation.py:450\u001b[0m, in \u001b[0;36mcross_validate\u001b[1;34m(estimator, X, y, groups, scoring, cv, n_jobs, verbose, fit_params, params, pre_dispatch, return_train_score, return_estimator, return_indices, error_score)\u001b[0m\n\u001b[0;32m    429\u001b[0m parallel \u001b[38;5;241m=\u001b[39m Parallel(n_jobs\u001b[38;5;241m=\u001b[39mn_jobs, verbose\u001b[38;5;241m=\u001b[39mverbose, pre_dispatch\u001b[38;5;241m=\u001b[39mpre_dispatch)\n\u001b[0;32m    430\u001b[0m results \u001b[38;5;241m=\u001b[39m parallel(\n\u001b[0;32m    431\u001b[0m     delayed(_fit_and_score)(\n\u001b[0;32m    432\u001b[0m         clone(estimator),\n\u001b[1;32m   (...)\u001b[0m\n\u001b[0;32m    447\u001b[0m     \u001b[38;5;28;01mfor\u001b[39;00m train, test \u001b[38;5;129;01min\u001b[39;00m indices\n\u001b[0;32m    448\u001b[0m )\n\u001b[1;32m--> 450\u001b[0m \u001b[43m_warn_or_raise_about_fit_failures\u001b[49m\u001b[43m(\u001b[49m\u001b[43mresults\u001b[49m\u001b[43m,\u001b[49m\u001b[43m \u001b[49m\u001b[43merror_score\u001b[49m\u001b[43m)\u001b[49m\n\u001b[0;32m    452\u001b[0m \u001b[38;5;66;03m# For callable scoring, the return type is only know after calling. If the\u001b[39;00m\n\u001b[0;32m    453\u001b[0m \u001b[38;5;66;03m# return type is a dictionary, the error scores can now be inserted with\u001b[39;00m\n\u001b[0;32m    454\u001b[0m \u001b[38;5;66;03m# the correct key.\u001b[39;00m\n\u001b[0;32m    455\u001b[0m \u001b[38;5;28;01mif\u001b[39;00m \u001b[38;5;28mcallable\u001b[39m(scoring):\n",
      "File \u001b[1;32mc:\\Users\\samue\\AppData\\Local\\Programs\\Python\\Python312\\Lib\\site-packages\\sklearn\\model_selection\\_validation.py:536\u001b[0m, in \u001b[0;36m_warn_or_raise_about_fit_failures\u001b[1;34m(results, error_score)\u001b[0m\n\u001b[0;32m    529\u001b[0m \u001b[38;5;28;01mif\u001b[39;00m num_failed_fits \u001b[38;5;241m==\u001b[39m num_fits:\n\u001b[0;32m    530\u001b[0m     all_fits_failed_message \u001b[38;5;241m=\u001b[39m (\n\u001b[0;32m    531\u001b[0m         \u001b[38;5;124mf\u001b[39m\u001b[38;5;124m\"\u001b[39m\u001b[38;5;130;01m\\n\u001b[39;00m\u001b[38;5;124mAll the \u001b[39m\u001b[38;5;132;01m{\u001b[39;00mnum_fits\u001b[38;5;132;01m}\u001b[39;00m\u001b[38;5;124m fits failed.\u001b[39m\u001b[38;5;130;01m\\n\u001b[39;00m\u001b[38;5;124m\"\u001b[39m\n\u001b[0;32m    532\u001b[0m         \u001b[38;5;124m\"\u001b[39m\u001b[38;5;124mIt is very likely that your model is misconfigured.\u001b[39m\u001b[38;5;130;01m\\n\u001b[39;00m\u001b[38;5;124m\"\u001b[39m\n\u001b[0;32m    533\u001b[0m         \u001b[38;5;124m\"\u001b[39m\u001b[38;5;124mYou can try to debug the error by setting error_score=\u001b[39m\u001b[38;5;124m'\u001b[39m\u001b[38;5;124mraise\u001b[39m\u001b[38;5;124m'\u001b[39m\u001b[38;5;124m.\u001b[39m\u001b[38;5;130;01m\\n\u001b[39;00m\u001b[38;5;130;01m\\n\u001b[39;00m\u001b[38;5;124m\"\u001b[39m\n\u001b[0;32m    534\u001b[0m         \u001b[38;5;124mf\u001b[39m\u001b[38;5;124m\"\u001b[39m\u001b[38;5;124mBelow are more details about the failures:\u001b[39m\u001b[38;5;130;01m\\n\u001b[39;00m\u001b[38;5;132;01m{\u001b[39;00mfit_errors_summary\u001b[38;5;132;01m}\u001b[39;00m\u001b[38;5;124m\"\u001b[39m\n\u001b[0;32m    535\u001b[0m     )\n\u001b[1;32m--> 536\u001b[0m     \u001b[38;5;28;01mraise\u001b[39;00m \u001b[38;5;167;01mValueError\u001b[39;00m(all_fits_failed_message)\n\u001b[0;32m    538\u001b[0m \u001b[38;5;28;01melse\u001b[39;00m:\n\u001b[0;32m    539\u001b[0m     some_fits_failed_message \u001b[38;5;241m=\u001b[39m (\n\u001b[0;32m    540\u001b[0m         \u001b[38;5;124mf\u001b[39m\u001b[38;5;124m\"\u001b[39m\u001b[38;5;130;01m\\n\u001b[39;00m\u001b[38;5;132;01m{\u001b[39;00mnum_failed_fits\u001b[38;5;132;01m}\u001b[39;00m\u001b[38;5;124m fits failed out of a total of \u001b[39m\u001b[38;5;132;01m{\u001b[39;00mnum_fits\u001b[38;5;132;01m}\u001b[39;00m\u001b[38;5;124m.\u001b[39m\u001b[38;5;130;01m\\n\u001b[39;00m\u001b[38;5;124m\"\u001b[39m\n\u001b[0;32m    541\u001b[0m         \u001b[38;5;124m\"\u001b[39m\u001b[38;5;124mThe score on these train-test partitions for these parameters\u001b[39m\u001b[38;5;124m\"\u001b[39m\n\u001b[1;32m   (...)\u001b[0m\n\u001b[0;32m    545\u001b[0m         \u001b[38;5;124mf\u001b[39m\u001b[38;5;124m\"\u001b[39m\u001b[38;5;124mBelow are more details about the failures:\u001b[39m\u001b[38;5;130;01m\\n\u001b[39;00m\u001b[38;5;132;01m{\u001b[39;00mfit_errors_summary\u001b[38;5;132;01m}\u001b[39;00m\u001b[38;5;124m\"\u001b[39m\n\u001b[0;32m    546\u001b[0m     )\n",
      "\u001b[1;31mValueError\u001b[0m: \nAll the 10 fits failed.\nIt is very likely that your model is misconfigured.\nYou can try to debug the error by setting error_score='raise'.\n\nBelow are more details about the failures:\n--------------------------------------------------------------------------------\n1 fits failed with the following error:\nTraceback (most recent call last):\n  File \"c:\\Users\\samue\\AppData\\Local\\Programs\\Python\\Python312\\Lib\\site-packages\\sklearn\\model_selection\\_validation.py\", line 895, in _fit_and_score\n    estimator.fit(X_train, y_train, **fit_params)\n  File \"c:\\Users\\samue\\AppData\\Local\\Programs\\Python\\Python312\\Lib\\site-packages\\scikeras\\wrappers.py\", line 770, in fit\n    self._fit(\n  File \"c:\\Users\\samue\\AppData\\Local\\Programs\\Python\\Python312\\Lib\\site-packages\\scikeras\\wrappers.py\", line 938, in _fit\n    self._fit_keras_model(\n  File \"c:\\Users\\samue\\AppData\\Local\\Programs\\Python\\Python312\\Lib\\site-packages\\scikeras\\wrappers.py\", line 535, in _fit_keras_model\n    hist = self.model_.fit(x=X, y=y, **fit_args)\n           ^^^^^^^^^^^^^^^^^^^^^^^^^^^^^^^^^^^^^\n  File \"c:\\Users\\samue\\AppData\\Local\\Programs\\Python\\Python312\\Lib\\site-packages\\keras\\src\\utils\\traceback_utils.py\", line 122, in error_handler\n    raise e.with_traceback(filtered_tb) from None\n  File \"c:\\Users\\samue\\AppData\\Local\\Programs\\Python\\Python312\\Lib\\site-packages\\keras\\src\\layers\\input_spec.py\", line 227, in assert_input_compatibility\n    raise ValueError(\nValueError: Exception encountered when calling Sequential.call().\n\n\u001b[1mInput 0 of layer \"dense_180\" is incompatible with the layer: expected axis -1 of input shape to have value 316, but received input with shape (None, 11)\u001b[0m\n\nArguments received by Sequential.call():\n  • inputs=tf.Tensor(shape=(None, 11), dtype=float32)\n  • training=True\n  • mask=None\n\n--------------------------------------------------------------------------------\n1 fits failed with the following error:\nTraceback (most recent call last):\n  File \"c:\\Users\\samue\\AppData\\Local\\Programs\\Python\\Python312\\Lib\\site-packages\\sklearn\\model_selection\\_validation.py\", line 895, in _fit_and_score\n    estimator.fit(X_train, y_train, **fit_params)\n  File \"c:\\Users\\samue\\AppData\\Local\\Programs\\Python\\Python312\\Lib\\site-packages\\scikeras\\wrappers.py\", line 770, in fit\n    self._fit(\n  File \"c:\\Users\\samue\\AppData\\Local\\Programs\\Python\\Python312\\Lib\\site-packages\\scikeras\\wrappers.py\", line 938, in _fit\n    self._fit_keras_model(\n  File \"c:\\Users\\samue\\AppData\\Local\\Programs\\Python\\Python312\\Lib\\site-packages\\scikeras\\wrappers.py\", line 535, in _fit_keras_model\n    hist = self.model_.fit(x=X, y=y, **fit_args)\n           ^^^^^^^^^^^^^^^^^^^^^^^^^^^^^^^^^^^^^\n  File \"c:\\Users\\samue\\AppData\\Local\\Programs\\Python\\Python312\\Lib\\site-packages\\keras\\src\\utils\\traceback_utils.py\", line 122, in error_handler\n    raise e.with_traceback(filtered_tb) from None\n  File \"c:\\Users\\samue\\AppData\\Local\\Programs\\Python\\Python312\\Lib\\site-packages\\keras\\src\\layers\\input_spec.py\", line 227, in assert_input_compatibility\n    raise ValueError(\nValueError: Exception encountered when calling Sequential.call().\n\n\u001b[1mInput 0 of layer \"dense_183\" is incompatible with the layer: expected axis -1 of input shape to have value 316, but received input with shape (None, 11)\u001b[0m\n\nArguments received by Sequential.call():\n  • inputs=tf.Tensor(shape=(None, 11), dtype=float32)\n  • training=True\n  • mask=None\n\n--------------------------------------------------------------------------------\n1 fits failed with the following error:\nTraceback (most recent call last):\n  File \"c:\\Users\\samue\\AppData\\Local\\Programs\\Python\\Python312\\Lib\\site-packages\\sklearn\\model_selection\\_validation.py\", line 895, in _fit_and_score\n    estimator.fit(X_train, y_train, **fit_params)\n  File \"c:\\Users\\samue\\AppData\\Local\\Programs\\Python\\Python312\\Lib\\site-packages\\scikeras\\wrappers.py\", line 770, in fit\n    self._fit(\n  File \"c:\\Users\\samue\\AppData\\Local\\Programs\\Python\\Python312\\Lib\\site-packages\\scikeras\\wrappers.py\", line 938, in _fit\n    self._fit_keras_model(\n  File \"c:\\Users\\samue\\AppData\\Local\\Programs\\Python\\Python312\\Lib\\site-packages\\scikeras\\wrappers.py\", line 535, in _fit_keras_model\n    hist = self.model_.fit(x=X, y=y, **fit_args)\n           ^^^^^^^^^^^^^^^^^^^^^^^^^^^^^^^^^^^^^\n  File \"c:\\Users\\samue\\AppData\\Local\\Programs\\Python\\Python312\\Lib\\site-packages\\keras\\src\\utils\\traceback_utils.py\", line 122, in error_handler\n    raise e.with_traceback(filtered_tb) from None\n  File \"c:\\Users\\samue\\AppData\\Local\\Programs\\Python\\Python312\\Lib\\site-packages\\keras\\src\\layers\\input_spec.py\", line 227, in assert_input_compatibility\n    raise ValueError(\nValueError: Exception encountered when calling Sequential.call().\n\n\u001b[1mInput 0 of layer \"dense_186\" is incompatible with the layer: expected axis -1 of input shape to have value 316, but received input with shape (None, 11)\u001b[0m\n\nArguments received by Sequential.call():\n  • inputs=tf.Tensor(shape=(None, 11), dtype=float32)\n  • training=True\n  • mask=None\n\n--------------------------------------------------------------------------------\n1 fits failed with the following error:\nTraceback (most recent call last):\n  File \"c:\\Users\\samue\\AppData\\Local\\Programs\\Python\\Python312\\Lib\\site-packages\\sklearn\\model_selection\\_validation.py\", line 895, in _fit_and_score\n    estimator.fit(X_train, y_train, **fit_params)\n  File \"c:\\Users\\samue\\AppData\\Local\\Programs\\Python\\Python312\\Lib\\site-packages\\scikeras\\wrappers.py\", line 770, in fit\n    self._fit(\n  File \"c:\\Users\\samue\\AppData\\Local\\Programs\\Python\\Python312\\Lib\\site-packages\\scikeras\\wrappers.py\", line 938, in _fit\n    self._fit_keras_model(\n  File \"c:\\Users\\samue\\AppData\\Local\\Programs\\Python\\Python312\\Lib\\site-packages\\scikeras\\wrappers.py\", line 535, in _fit_keras_model\n    hist = self.model_.fit(x=X, y=y, **fit_args)\n           ^^^^^^^^^^^^^^^^^^^^^^^^^^^^^^^^^^^^^\n  File \"c:\\Users\\samue\\AppData\\Local\\Programs\\Python\\Python312\\Lib\\site-packages\\keras\\src\\utils\\traceback_utils.py\", line 122, in error_handler\n    raise e.with_traceback(filtered_tb) from None\n  File \"c:\\Users\\samue\\AppData\\Local\\Programs\\Python\\Python312\\Lib\\site-packages\\keras\\src\\layers\\input_spec.py\", line 227, in assert_input_compatibility\n    raise ValueError(\nValueError: Exception encountered when calling Sequential.call().\n\n\u001b[1mInput 0 of layer \"dense_189\" is incompatible with the layer: expected axis -1 of input shape to have value 316, but received input with shape (None, 11)\u001b[0m\n\nArguments received by Sequential.call():\n  • inputs=tf.Tensor(shape=(None, 11), dtype=float32)\n  • training=True\n  • mask=None\n\n--------------------------------------------------------------------------------\n1 fits failed with the following error:\nTraceback (most recent call last):\n  File \"c:\\Users\\samue\\AppData\\Local\\Programs\\Python\\Python312\\Lib\\site-packages\\sklearn\\model_selection\\_validation.py\", line 895, in _fit_and_score\n    estimator.fit(X_train, y_train, **fit_params)\n  File \"c:\\Users\\samue\\AppData\\Local\\Programs\\Python\\Python312\\Lib\\site-packages\\scikeras\\wrappers.py\", line 770, in fit\n    self._fit(\n  File \"c:\\Users\\samue\\AppData\\Local\\Programs\\Python\\Python312\\Lib\\site-packages\\scikeras\\wrappers.py\", line 938, in _fit\n    self._fit_keras_model(\n  File \"c:\\Users\\samue\\AppData\\Local\\Programs\\Python\\Python312\\Lib\\site-packages\\scikeras\\wrappers.py\", line 535, in _fit_keras_model\n    hist = self.model_.fit(x=X, y=y, **fit_args)\n           ^^^^^^^^^^^^^^^^^^^^^^^^^^^^^^^^^^^^^\n  File \"c:\\Users\\samue\\AppData\\Local\\Programs\\Python\\Python312\\Lib\\site-packages\\keras\\src\\utils\\traceback_utils.py\", line 122, in error_handler\n    raise e.with_traceback(filtered_tb) from None\n  File \"c:\\Users\\samue\\AppData\\Local\\Programs\\Python\\Python312\\Lib\\site-packages\\keras\\src\\layers\\input_spec.py\", line 227, in assert_input_compatibility\n    raise ValueError(\nValueError: Exception encountered when calling Sequential.call().\n\n\u001b[1mInput 0 of layer \"dense_192\" is incompatible with the layer: expected axis -1 of input shape to have value 316, but received input with shape (None, 11)\u001b[0m\n\nArguments received by Sequential.call():\n  • inputs=tf.Tensor(shape=(None, 11), dtype=float32)\n  • training=True\n  • mask=None\n\n--------------------------------------------------------------------------------\n1 fits failed with the following error:\nTraceback (most recent call last):\n  File \"c:\\Users\\samue\\AppData\\Local\\Programs\\Python\\Python312\\Lib\\site-packages\\sklearn\\model_selection\\_validation.py\", line 895, in _fit_and_score\n    estimator.fit(X_train, y_train, **fit_params)\n  File \"c:\\Users\\samue\\AppData\\Local\\Programs\\Python\\Python312\\Lib\\site-packages\\scikeras\\wrappers.py\", line 770, in fit\n    self._fit(\n  File \"c:\\Users\\samue\\AppData\\Local\\Programs\\Python\\Python312\\Lib\\site-packages\\scikeras\\wrappers.py\", line 938, in _fit\n    self._fit_keras_model(\n  File \"c:\\Users\\samue\\AppData\\Local\\Programs\\Python\\Python312\\Lib\\site-packages\\scikeras\\wrappers.py\", line 535, in _fit_keras_model\n    hist = self.model_.fit(x=X, y=y, **fit_args)\n           ^^^^^^^^^^^^^^^^^^^^^^^^^^^^^^^^^^^^^\n  File \"c:\\Users\\samue\\AppData\\Local\\Programs\\Python\\Python312\\Lib\\site-packages\\keras\\src\\utils\\traceback_utils.py\", line 122, in error_handler\n    raise e.with_traceback(filtered_tb) from None\n  File \"c:\\Users\\samue\\AppData\\Local\\Programs\\Python\\Python312\\Lib\\site-packages\\keras\\src\\layers\\input_spec.py\", line 227, in assert_input_compatibility\n    raise ValueError(\nValueError: Exception encountered when calling Sequential.call().\n\n\u001b[1mInput 0 of layer \"dense_195\" is incompatible with the layer: expected axis -1 of input shape to have value 316, but received input with shape (None, 11)\u001b[0m\n\nArguments received by Sequential.call():\n  • inputs=tf.Tensor(shape=(None, 11), dtype=float32)\n  • training=True\n  • mask=None\n\n--------------------------------------------------------------------------------\n1 fits failed with the following error:\nTraceback (most recent call last):\n  File \"c:\\Users\\samue\\AppData\\Local\\Programs\\Python\\Python312\\Lib\\site-packages\\sklearn\\model_selection\\_validation.py\", line 895, in _fit_and_score\n    estimator.fit(X_train, y_train, **fit_params)\n  File \"c:\\Users\\samue\\AppData\\Local\\Programs\\Python\\Python312\\Lib\\site-packages\\scikeras\\wrappers.py\", line 770, in fit\n    self._fit(\n  File \"c:\\Users\\samue\\AppData\\Local\\Programs\\Python\\Python312\\Lib\\site-packages\\scikeras\\wrappers.py\", line 938, in _fit\n    self._fit_keras_model(\n  File \"c:\\Users\\samue\\AppData\\Local\\Programs\\Python\\Python312\\Lib\\site-packages\\scikeras\\wrappers.py\", line 535, in _fit_keras_model\n    hist = self.model_.fit(x=X, y=y, **fit_args)\n           ^^^^^^^^^^^^^^^^^^^^^^^^^^^^^^^^^^^^^\n  File \"c:\\Users\\samue\\AppData\\Local\\Programs\\Python\\Python312\\Lib\\site-packages\\keras\\src\\utils\\traceback_utils.py\", line 122, in error_handler\n    raise e.with_traceback(filtered_tb) from None\n  File \"c:\\Users\\samue\\AppData\\Local\\Programs\\Python\\Python312\\Lib\\site-packages\\keras\\src\\layers\\input_spec.py\", line 227, in assert_input_compatibility\n    raise ValueError(\nValueError: Exception encountered when calling Sequential.call().\n\n\u001b[1mInput 0 of layer \"dense_198\" is incompatible with the layer: expected axis -1 of input shape to have value 316, but received input with shape (None, 11)\u001b[0m\n\nArguments received by Sequential.call():\n  • inputs=tf.Tensor(shape=(None, 11), dtype=float32)\n  • training=True\n  • mask=None\n\n--------------------------------------------------------------------------------\n1 fits failed with the following error:\nTraceback (most recent call last):\n  File \"c:\\Users\\samue\\AppData\\Local\\Programs\\Python\\Python312\\Lib\\site-packages\\sklearn\\model_selection\\_validation.py\", line 895, in _fit_and_score\n    estimator.fit(X_train, y_train, **fit_params)\n  File \"c:\\Users\\samue\\AppData\\Local\\Programs\\Python\\Python312\\Lib\\site-packages\\scikeras\\wrappers.py\", line 770, in fit\n    self._fit(\n  File \"c:\\Users\\samue\\AppData\\Local\\Programs\\Python\\Python312\\Lib\\site-packages\\scikeras\\wrappers.py\", line 938, in _fit\n    self._fit_keras_model(\n  File \"c:\\Users\\samue\\AppData\\Local\\Programs\\Python\\Python312\\Lib\\site-packages\\scikeras\\wrappers.py\", line 535, in _fit_keras_model\n    hist = self.model_.fit(x=X, y=y, **fit_args)\n           ^^^^^^^^^^^^^^^^^^^^^^^^^^^^^^^^^^^^^\n  File \"c:\\Users\\samue\\AppData\\Local\\Programs\\Python\\Python312\\Lib\\site-packages\\keras\\src\\utils\\traceback_utils.py\", line 122, in error_handler\n    raise e.with_traceback(filtered_tb) from None\n  File \"c:\\Users\\samue\\AppData\\Local\\Programs\\Python\\Python312\\Lib\\site-packages\\keras\\src\\layers\\input_spec.py\", line 227, in assert_input_compatibility\n    raise ValueError(\nValueError: Exception encountered when calling Sequential.call().\n\n\u001b[1mInput 0 of layer \"dense_201\" is incompatible with the layer: expected axis -1 of input shape to have value 316, but received input with shape (None, 11)\u001b[0m\n\nArguments received by Sequential.call():\n  • inputs=tf.Tensor(shape=(None, 11), dtype=float32)\n  • training=True\n  • mask=None\n\n--------------------------------------------------------------------------------\n1 fits failed with the following error:\nTraceback (most recent call last):\n  File \"c:\\Users\\samue\\AppData\\Local\\Programs\\Python\\Python312\\Lib\\site-packages\\sklearn\\model_selection\\_validation.py\", line 895, in _fit_and_score\n    estimator.fit(X_train, y_train, **fit_params)\n  File \"c:\\Users\\samue\\AppData\\Local\\Programs\\Python\\Python312\\Lib\\site-packages\\scikeras\\wrappers.py\", line 770, in fit\n    self._fit(\n  File \"c:\\Users\\samue\\AppData\\Local\\Programs\\Python\\Python312\\Lib\\site-packages\\scikeras\\wrappers.py\", line 938, in _fit\n    self._fit_keras_model(\n  File \"c:\\Users\\samue\\AppData\\Local\\Programs\\Python\\Python312\\Lib\\site-packages\\scikeras\\wrappers.py\", line 535, in _fit_keras_model\n    hist = self.model_.fit(x=X, y=y, **fit_args)\n           ^^^^^^^^^^^^^^^^^^^^^^^^^^^^^^^^^^^^^\n  File \"c:\\Users\\samue\\AppData\\Local\\Programs\\Python\\Python312\\Lib\\site-packages\\keras\\src\\utils\\traceback_utils.py\", line 122, in error_handler\n    raise e.with_traceback(filtered_tb) from None\n  File \"c:\\Users\\samue\\AppData\\Local\\Programs\\Python\\Python312\\Lib\\site-packages\\keras\\src\\layers\\input_spec.py\", line 227, in assert_input_compatibility\n    raise ValueError(\nValueError: Exception encountered when calling Sequential.call().\n\n\u001b[1mInput 0 of layer \"dense_204\" is incompatible with the layer: expected axis -1 of input shape to have value 316, but received input with shape (None, 11)\u001b[0m\n\nArguments received by Sequential.call():\n  • inputs=tf.Tensor(shape=(None, 11), dtype=float32)\n  • training=True\n  • mask=None\n\n--------------------------------------------------------------------------------\n1 fits failed with the following error:\nTraceback (most recent call last):\n  File \"c:\\Users\\samue\\AppData\\Local\\Programs\\Python\\Python312\\Lib\\site-packages\\sklearn\\model_selection\\_validation.py\", line 895, in _fit_and_score\n    estimator.fit(X_train, y_train, **fit_params)\n  File \"c:\\Users\\samue\\AppData\\Local\\Programs\\Python\\Python312\\Lib\\site-packages\\scikeras\\wrappers.py\", line 770, in fit\n    self._fit(\n  File \"c:\\Users\\samue\\AppData\\Local\\Programs\\Python\\Python312\\Lib\\site-packages\\scikeras\\wrappers.py\", line 938, in _fit\n    self._fit_keras_model(\n  File \"c:\\Users\\samue\\AppData\\Local\\Programs\\Python\\Python312\\Lib\\site-packages\\scikeras\\wrappers.py\", line 535, in _fit_keras_model\n    hist = self.model_.fit(x=X, y=y, **fit_args)\n           ^^^^^^^^^^^^^^^^^^^^^^^^^^^^^^^^^^^^^\n  File \"c:\\Users\\samue\\AppData\\Local\\Programs\\Python\\Python312\\Lib\\site-packages\\keras\\src\\utils\\traceback_utils.py\", line 122, in error_handler\n    raise e.with_traceback(filtered_tb) from None\n  File \"c:\\Users\\samue\\AppData\\Local\\Programs\\Python\\Python312\\Lib\\site-packages\\keras\\src\\layers\\input_spec.py\", line 227, in assert_input_compatibility\n    raise ValueError(\nValueError: Exception encountered when calling Sequential.call().\n\n\u001b[1mInput 0 of layer \"dense_207\" is incompatible with the layer: expected axis -1 of input shape to have value 316, but received input with shape (None, 11)\u001b[0m\n\nArguments received by Sequential.call():\n  • inputs=tf.Tensor(shape=(None, 11), dtype=float32)\n  • training=True\n  • mask=None\n"
     ]
    }
   ],
   "source": [
    "resultados = cross_val_score(estimator=regressor, X=previsores, y=preco_real, cv=10, scoring='neg_mean_absolute_error')"
   ]
  }
 ],
 "metadata": {
  "kernelspec": {
   "display_name": "Python 3",
   "language": "python",
   "name": "python3"
  },
  "language_info": {
   "codemirror_mode": {
    "name": "ipython",
    "version": 3
   },
   "file_extension": ".py",
   "mimetype": "text/x-python",
   "name": "python",
   "nbconvert_exporter": "python",
   "pygments_lexer": "ipython3",
   "version": "3.12.3"
  }
 },
 "nbformat": 4,
 "nbformat_minor": 2
}
