{
 "cells": [
  {
   "cell_type": "code",
   "execution_count": 15,
   "metadata": {},
   "outputs": [],
   "source": [
    "import pandas as pd\n",
    "from sklearn.model_selection import train_test_split \n",
    "from keras.models import Sequential\n",
    "from keras.layers import Dense\n",
    "from tensorflow.keras.utils import to_categorical\n",
    "from sklearn.preprocessing import LabelEncoder"
   ]
  },
  {
   "cell_type": "code",
   "execution_count": 2,
   "metadata": {},
   "outputs": [],
   "source": [
    "base = pd.read_csv('iris.csv')\n",
    "previsores = base.iloc[:, 0:4].values\n",
    "classe = base.iloc[:, 4].values"
   ]
  },
  {
   "cell_type": "code",
   "execution_count": 16,
   "metadata": {},
   "outputs": [],
   "source": [
    "labelencoder = LabelEncoder()\n",
    "classe = labelencoder.fit_transform(classe)\n",
    "classe_dummy = to_categorical(classe)"
   ]
  },
  {
   "cell_type": "code",
   "execution_count": 5,
   "metadata": {},
   "outputs": [],
   "source": [
    "previsores_treinamento, previsores_teste, classe_treinamento, classe_teste = train_test_split(previsores, classe, test_size = 0.25 )"
   ]
  },
  {
   "cell_type": "code",
   "execution_count": 7,
   "metadata": {},
   "outputs": [
    {
     "name": "stderr",
     "output_type": "stream",
     "text": [
      "c:\\Users\\samue\\AppData\\Local\\Programs\\Python\\Python312\\Lib\\site-packages\\keras\\src\\layers\\core\\dense.py:87: UserWarning: Do not pass an `input_shape`/`input_dim` argument to a layer. When using Sequential models, prefer using an `Input(shape)` object as the first layer in the model instead.\n",
      "  super().__init__(activity_regularizer=activity_regularizer, **kwargs)\n"
     ]
    }
   ],
   "source": [
    "classificador = Sequential()\n",
    "classificador.add(Dense(units = 4, activation = 'relu', input_dim = 4))\n",
    "classificador.add(Dense(units = 4, activation = 'relu'))\n",
    "classificador.add(Dense(units = 3, activation = 'softmax'))\n",
    "classificador.compile(optimizer = 'adam', loss = 'categorical_crosssentropy', metrics = ['categorical_accuracy'])"
   ]
  },
  {
   "cell_type": "code",
   "execution_count": 8,
   "metadata": {},
   "outputs": [
    {
     "name": "stdout",
     "output_type": "stream",
     "text": [
      "Epoch 1/1000\n"
     ]
    },
    {
     "ename": "ValueError",
     "evalue": "Could not interpret loss identifier: categorical_crosssentropy",
     "output_type": "error",
     "traceback": [
      "\u001b[1;31m---------------------------------------------------------------------------\u001b[0m",
      "\u001b[1;31mValueError\u001b[0m                                Traceback (most recent call last)",
      "Cell \u001b[1;32mIn[8], line 1\u001b[0m\n\u001b[1;32m----> 1\u001b[0m \u001b[43mclassificador\u001b[49m\u001b[38;5;241;43m.\u001b[39;49m\u001b[43mfit\u001b[49m\u001b[43m(\u001b[49m\u001b[43mprevisores_treinamento\u001b[49m\u001b[43m,\u001b[49m\u001b[43m \u001b[49m\u001b[43mclasse_treinamento\u001b[49m\u001b[43m,\u001b[49m\u001b[43m \u001b[49m\u001b[43mbatch_size\u001b[49m\u001b[43m \u001b[49m\u001b[38;5;241;43m=\u001b[39;49m\u001b[43m \u001b[49m\u001b[38;5;241;43m10\u001b[39;49m\u001b[43m,\u001b[49m\u001b[43m \u001b[49m\u001b[43mepochs\u001b[49m\u001b[43m \u001b[49m\u001b[38;5;241;43m=\u001b[39;49m\u001b[43m \u001b[49m\u001b[38;5;241;43m1000\u001b[39;49m\u001b[43m)\u001b[49m\n",
      "File \u001b[1;32mc:\\Users\\samue\\AppData\\Local\\Programs\\Python\\Python312\\Lib\\site-packages\\keras\\src\\utils\\traceback_utils.py:122\u001b[0m, in \u001b[0;36mfilter_traceback.<locals>.error_handler\u001b[1;34m(*args, **kwargs)\u001b[0m\n\u001b[0;32m    119\u001b[0m     filtered_tb \u001b[38;5;241m=\u001b[39m _process_traceback_frames(e\u001b[38;5;241m.\u001b[39m__traceback__)\n\u001b[0;32m    120\u001b[0m     \u001b[38;5;66;03m# To get the full stack trace, call:\u001b[39;00m\n\u001b[0;32m    121\u001b[0m     \u001b[38;5;66;03m# `keras.config.disable_traceback_filtering()`\u001b[39;00m\n\u001b[1;32m--> 122\u001b[0m     \u001b[38;5;28;01mraise\u001b[39;00m e\u001b[38;5;241m.\u001b[39mwith_traceback(filtered_tb) \u001b[38;5;28;01mfrom\u001b[39;00m \u001b[38;5;28;01mNone\u001b[39;00m\n\u001b[0;32m    123\u001b[0m \u001b[38;5;28;01mfinally\u001b[39;00m:\n\u001b[0;32m    124\u001b[0m     \u001b[38;5;28;01mdel\u001b[39;00m filtered_tb\n",
      "File \u001b[1;32mc:\\Users\\samue\\AppData\\Local\\Programs\\Python\\Python312\\Lib\\site-packages\\keras\\src\\losses\\__init__.py:196\u001b[0m, in \u001b[0;36mget\u001b[1;34m(identifier)\u001b[0m\n\u001b[0;32m    194\u001b[0m     \u001b[38;5;28;01mreturn\u001b[39;00m obj\n\u001b[0;32m    195\u001b[0m \u001b[38;5;28;01melse\u001b[39;00m:\n\u001b[1;32m--> 196\u001b[0m     \u001b[38;5;28;01mraise\u001b[39;00m \u001b[38;5;167;01mValueError\u001b[39;00m(\u001b[38;5;124mf\u001b[39m\u001b[38;5;124m\"\u001b[39m\u001b[38;5;124mCould not interpret loss identifier: \u001b[39m\u001b[38;5;132;01m{\u001b[39;00midentifier\u001b[38;5;132;01m}\u001b[39;00m\u001b[38;5;124m\"\u001b[39m)\n",
      "\u001b[1;31mValueError\u001b[0m: Could not interpret loss identifier: categorical_crosssentropy"
     ]
    }
   ],
   "source": [
    "classificador.fit(previsores_treinamento, classe_treinamento, batch_size = 10, epochs = 1000)"
   ]
  }
 ],
 "metadata": {
  "kernelspec": {
   "display_name": "Python 3",
   "language": "python",
   "name": "python3"
  },
  "language_info": {
   "codemirror_mode": {
    "name": "ipython",
    "version": 3
   },
   "file_extension": ".py",
   "mimetype": "text/x-python",
   "name": "python",
   "nbconvert_exporter": "python",
   "pygments_lexer": "ipython3",
   "version": "3.12.3"
  }
 },
 "nbformat": 4,
 "nbformat_minor": 2
}
